Traceback (most recent call last):
  File "./random_traceback.py", line 113, in get_random_error_string
  File "./random_traceback.py", line 86, in get_attributes
  File "./random_traceback.py", line 59, in get_data
ConflictError: Mismatched argumnets
2019-03-03 13:18:36.165272 INFO publisher.py:148 Node created
Traceback (most recent call last):
  File "./random_traceback.py", line 113, in get_random_error_string
  File "./random_traceback.py", line 92, in get_attributes
InvalidArgumentError: Provided too few arguments
2019-03-03 13:18:36.621841 ERROR ssh_tunnel.py:364 Fanning out RPC
2019-03-03 13:18:36.723700 DBG scheduler.py:80 Fanning out RPC
2019-03-03 13:18:37.231286 ERROR fanout.py:323 Gathering logs from all nodes
2019-03-03 13:18:38.146692 INFO alert_manager.py:78 Node created
2019-03-03 13:18:38.247638 DBG audit_logger.py:43 Gathering node data
2019-03-03 13:18:38.398983 INFO rpc_client.py:315 Generated binary file
2019-03-03 13:18:39.051303 ERROR task_generator.py:90 Combining logs from all nodes into single log file
2019-03-03 13:18:39.606223 DBG audit_logger.py:177 Generated binary file
2019-03-03 13:18:39.656443 DBG audit_logger.py:391 Fanning out RPC
2019-03-03 13:18:40.111400 INFO publisher.py:330 Node created
2019-03-03 13:18:41.121892 ERROR db_write.py:284 Generated binary file
2019-03-03 13:18:41.273353 INFO task_generator.py:226 Gathering node data
2019-03-03 13:18:41.576827 INFO ssh_tunnel.py:112 Gathering logs from all nodes
2019-03-03 13:18:41.779451 DBG task_generator.py:360 Creating task
2019-03-03 13:18:42.081513 ERROR http_handler.py:6 Generated binary file
2019-03-03 13:18:42.131922 INFO http_handler.py:91 Combining logs from all nodes into single log file
2019-03-03 13:18:42.434469 ERROR wsgi_handler.py:80 Gathering logs from all nodes
2019-03-03 13:18:42.485066 INFO http_handler.py:286 Combining logs from all nodes into single log file
2019-03-03 13:18:42.585810 ERROR fanout.py:242 Node destroyed
2019-03-03 13:18:42.888397 DBG db_write.py:168 Fanning out RPC
2019-03-03 13:18:43.039885 INFO fanout.py:332 Node created
2019-03-03 13:18:43.190945 ERROR protobuf_parser.py:363 Creating task
2019-03-03 13:18:43.493570 ERROR task_generator.py:102 Node created
2019-03-03 13:18:43.745315 ERROR db_read.py:363 Node destroyed
Traceback (most recent call last):
  File "./random_traceback.py", line 113, in get_random_error_string
  File "./random_traceback.py", line 88, in get_attributes
  File "./random_traceback.py", line 88, in get_attributes
  File "./random_traceback.py", line 92, in get_attributes
BasicAuthRequiredError: Password not provided
2019-03-03 13:18:44.098886 INFO gflags_handler.py:41 Generated binary file
2019-03-03 13:18:44.250073 INFO http_handler.py:167 Gathering node data
Traceback (most recent call last):
  File "./random_traceback.py", line 113, in get_random_error_string
  File "./random_traceback.py", line 92, in get_attributes
InvalidArgumentError: Provided too many arguments
2019-03-03 13:18:44.905501 DBG wsgi_handler.py:117 Creating task
2019-03-03 13:18:45.056771 DBG publisher.py:396 Node destroyed
2019-03-03 13:18:45.157450 INFO http_handler.py:160 Node created
2019-03-03 13:18:45.308773 ERROR ssh_tunnel.py:310 Creating task
Traceback (most recent call last):
  File "./random_traceback.py", line 103, in get_random_error_string
  File "./random_traceback.py", line 64, in extract_metadata
  File "./random_traceback.py", line 88, in get_attributes
  File "./random_traceback.py", line 88, in get_attributes
  File "./random_traceback.py", line 92, in get_attributes
BasicAuthRequiredError: Password not provided
2019-03-03 13:18:45.662713 INFO scheduler.py:80 Fanning out RPC
2019-03-03 13:18:45.763298 DBG audit_logger.py:70 Generated binary file
2019-03-03 13:18:45.864001 DBG publisher.py:200 Gathering logs from all nodes
2019-03-03 13:18:46.519911 DBG gflags_handler.py:314 Gathering logs from all nodes
2019-03-03 13:18:46.671301 INFO alert_manager.py:144 Creating task
2019-03-03 13:18:47.074835 INFO wsgi_handler.py:335 Gathering logs from all nodes
2019-03-03 13:18:47.276984 INFO fanout.py:398 Gathering node data
Traceback (most recent call last):
  File "./random_traceback.py", line 98, in get_random_error_string
  File "./random_traceback.py", line 55, in get_data
  File "./random_traceback.py", line 75, in return_output
  File "./random_traceback.py", line 70, in extract_metadata
ConflictError: Data structure not supported
2019-03-03 13:18:47.530439 INFO task_generator.py:379 Node created
2019-03-03 13:18:47.681741 DBG scheduler.py:90 Gathering logs from all nodes
Traceback (most recent call last):
  File "./random_traceback.py", line 98, in get_random_error_string
  File "./random_traceback.py", line 55, in get_data
  File "./random_traceback.py", line 77, in return_output
  File "./random_traceback.py", line 59, in get_data
BasicAuthRequiredError: Invalid authentication
2019-03-03 13:18:48.034779 ERROR task_generator.py:364 Generated binary file
2019-03-03 13:18:48.085079 ERROR db_write.py:189 Generated binary file
2019-03-03 13:18:48.185825 DBG alert_manager.py:295 Gathering logs from all nodes
2019-03-03 13:18:48.236175 ERROR db_read.py:55 Combining logs from all nodes into single log file
2019-03-03 13:18:48.336698 DBG ssh_tunnel.py:126 Node created
Traceback (most recent call last):
  File "./random_traceback.py", line 113, in get_random_error_string
  File "./random_traceback.py", line 86, in get_attributes
  File "./random_traceback.py", line 59, in get_data
MissingAttributeError: Attribute missing
2019-03-03 13:18:48.640441 ERROR audit_logger.py:2 Generated binary file
2019-03-03 13:18:49.548359 INFO fanout.py:373 Combining logs from all nodes into single log file
2019-03-03 13:18:50.303708 INFO http_handler.py:70 Node created
2019-03-03 13:18:50.555650 INFO scheduler.py:76 Fanning out RPC
2019-03-03 13:18:50.757156 ERROR task_generator.py:119 Creating task
Traceback (most recent call last):
  File "./random_traceback.py", line 113, in get_random_error_string
  File "./random_traceback.py", line 92, in get_attributes
InvalidArgumentError: Unable to parse arguments
2019-03-03 13:18:51.059906 ERROR gflags_handler.py:346 Gathering logs from all nodes
2019-03-03 13:18:51.312120 INFO wsgi_handler.py:153 Generated binary file
2019-03-03 13:18:51.362394 INFO log_collector.py:314 Node destroyed
2019-03-03 13:18:51.463026 DBG audit_logger.py:112 Node destroyed
2019-03-03 13:18:51.765554 INFO fanout.py:9 Gathering node data
2019-03-03 13:18:52.017092 INFO alert_manager.py:247 Fanning out RPC
2019-03-03 13:18:52.519248 DBG task_generator.py:219 Node destroyed
Traceback (most recent call last):
  File "./random_traceback.py", line 113, in get_random_error_string
  File "./random_traceback.py", line 86, in get_attributes
  File "./random_traceback.py", line 53, in get_data
  File "./random_traceback.py", line 66, in extract_metadata
  File "./random_traceback.py", line 81, in return_output
MissingAttributeError: Attribute not provided
Traceback (most recent call last):
  File "./random_traceback.py", line 108, in get_random_error_string
  File "./random_traceback.py", line 81, in return_output
MissingAttributeError: Attribute missing
2019-03-03 13:18:52.772176 DBG rpc_client.py:385 Node created
2019-03-03 13:18:53.377724 DBG fanout.py:177 Combining logs from all nodes into single log file
2019-03-03 13:18:53.428079 INFO db_write.py:84 Node destroyed
2019-03-03 13:18:53.528814 INFO scheduler.py:78 Combining logs from all nodes into single log file
2019-03-03 13:18:54.082336 ERROR scheduler.py:172 Gathering logs from all nodes
2019-03-03 13:18:54.334643 ERROR wsgi_handler.py:249 Fanning out RPC
2019-03-03 13:18:54.384914 DBG task_generator.py:366 Fanning out RPC
2019-03-03 13:18:54.435158 ERROR scheduler.py:154 Node created
2019-03-03 13:18:54.485374 ERROR scheduler.py:64 Fanning out RPC
2019-03-03 13:18:54.636330 DBG log_collector.py:196 Combining logs from all nodes into single log file
2019-03-03 13:18:54.938905 ERROR http_handler.py:332 Fanning out RPC
2019-03-03 13:18:55.139767 INFO scheduler.py:11 Node created
2019-03-03 13:18:55.190108 ERROR db_write.py:245 Creating task
2019-03-03 13:18:55.494063 INFO fanout.py:249 Node destroyed
2019-03-03 13:18:55.647040 ERROR publisher.py:316 Gathering node data
2019-03-03 13:18:55.697227 INFO scheduler.py:294 Generated binary file
2019-03-03 13:18:55.898679 INFO rpc_client.py:137 Node destroyed
2019-03-03 13:18:56.102926 INFO protobuf_parser.py:289 Generated binary file
2019-03-03 13:18:56.358055 ERROR db_write.py:43 Gathering logs from all nodes
Traceback (most recent call last):
  File "./random_traceback.py", line 108, in get_random_error_string
  File "./random_traceback.py", line 81, in return_output
BadRequestError: Request buffer too large
2019-03-03 13:18:57.430640 ERROR protobuf_parser.py:85 Generated binary file
2019-03-03 13:18:57.735443 ERROR audit_logger.py:243 Generated binary file
2019-03-03 13:18:58.092142 DBG scheduler.py:219 Creating task
2019-03-03 13:18:58.702166 DBG db_write.py:194 Gathering logs from all nodes
Traceback (most recent call last):
  File "./random_traceback.py", line 108, in get_random_error_string
  File "./random_traceback.py", line 75, in return_output
  File "./random_traceback.py", line 70, in extract_metadata
ConflictError: Data structure not supported
2019-03-03 13:18:59.511975 DBG db_read.py:3 Fanning out RPC
2019-03-03 13:18:59.613315 ERROR task_generator.py:98 Gathering node data
2019-03-03 13:18:59.865745 ERROR gflags_handler.py:233 Generated binary file
2019-03-03 13:19:00.066491 ERROR rpc_client.py:89 Combining logs from all nodes into single log file
2019-03-03 13:19:00.419582 ERROR scheduler.py:277 Fanning out RPC
2019-03-03 13:19:00.519882 INFO db_read.py:393 Node created
Traceback (most recent call last):
  File "./random_traceback.py", line 103, in get_random_error_string
  File "./random_traceback.py", line 70, in extract_metadata
MissingAttributeError: Attribute not provided
Traceback (most recent call last):
  File "./random_traceback.py", line 108, in get_random_error_string
  File "./random_traceback.py", line 81, in return_output
MissingAttributeError: Extra attribute needed
2019-03-03 13:19:00.922606 ERROR wsgi_handler.py:352 Gathering node data
2019-03-03 13:19:00.972864 ERROR alert_manager.py:342 Generated binary file
2019-03-03 13:19:01.023216 ERROR alert_manager.py:240 Node destroyed
2019-03-03 13:19:01.076966 DBG publisher.py:337 Node destroyed
2019-03-03 13:19:01.278072 INFO rpc_client.py:258 Generated binary file
2019-03-03 13:19:01.782543 DBG task_generator.py:67 Generated binary file
2019-03-03 13:19:01.833076 INFO rpc_client.py:67 Gathering logs from all nodes
2019-03-03 13:19:01.934985 INFO scheduler.py:63 Creating task
2019-03-03 13:19:02.290172 ERROR rpc_client.py:193 Fanning out RPC
2019-03-03 13:19:02.492018 INFO alert_manager.py:250 Node created
2019-03-03 13:19:02.694781 INFO publisher.py:94 Combining logs from all nodes into single log file
