2019-03-03 13:18:35.150391 ERROR http_handler.py:108 Gathering logs from all nodes
2019-03-03 13:18:35.251120 INFO publisher.py:72 Combining logs from all nodes into single log file
2019-03-03 13:18:35.353043 INFO db_read.py:342 Fanning out RPC
Traceback (most recent call last):
  File "./random_traceback.py", line 103, in get_random_error_string
  File "./random_traceback.py", line 66, in extract_metadata
  File "./random_traceback.py", line 81, in return_output
BasicAuthRequiredError: Invalid authentication
2019-03-03 13:18:35.558811 DBG scheduler.py:103 Node destroyed
2019-03-03 13:18:35.761452 ERROR wsgi_handler.py:156 Creating task
2019-03-03 13:18:35.862304 DBG rpc_client.py:230 Generated binary file
2019-03-03 13:18:35.962843 DBG alert_manager.py:184 Fanning out RPC
2019-03-03 13:18:36.115045 ERROR http_handler.py:288 Combining logs from all nodes into single log file
2019-03-03 13:18:36.369065 ERROR audit_logger.py:348 Creating task
Traceback (most recent call last):
  File "./random_traceback.py", line 113, in get_random_error_string
  File "./random_traceback.py", line 86, in get_attributes
  File "./random_traceback.py", line 59, in get_data
ConflictError: Mismatched argumnets
2019-03-03 13:18:36.775207 DBG wsgi_handler.py:382 Gathering logs from all nodes
Traceback (most recent call last):
  File "./random_traceback.py", line 113, in get_random_error_string
  File "./random_traceback.py", line 92, in get_attributes
ConflictError: Data structure not supported
2019-03-03 13:18:37.180871 DBG log_collector.py:320 Combining logs from all nodes into single log file
2019-03-03 13:18:37.432960 DBG task_generator.py:300 Generated binary file
2019-03-03 13:18:37.586865 DBG rpc_client.py:253 Node created
2019-03-03 13:18:37.689185 ERROR audit_logger.py:93 Gathering node data
2019-03-03 13:18:38.197137 ERROR task_generator.py:241 Gathering logs from all nodes
2019-03-03 13:18:38.800428 INFO scheduler.py:70 Combining logs from all nodes into single log file
2019-03-03 13:18:38.850598 ERROR fanout.py:284 Creating task
2019-03-03 13:18:38.900784 ERROR alert_manager.py:114 Fanning out RPC
2019-03-03 13:18:38.950958 DBG wsgi_handler.py:12 Node created
2019-03-03 13:18:39.253646 DBG task_generator.py:246 Node destroyed
Traceback (most recent call last):
  File "./random_traceback.py", line 98, in get_random_error_string
  File "./random_traceback.py", line 53, in get_data
  File "./random_traceback.py", line 70, in extract_metadata
BasicAuthRequiredError: Password not provided
2019-03-03 13:18:40.869192 ERROR fanout.py:228 Gathering logs from all nodes
2019-03-03 13:18:40.919727 ERROR publisher.py:181 Gathering logs from all nodes
2019-03-03 13:18:40.970246 ERROR db_read.py:26 Gathering logs from all nodes
2019-03-03 13:18:41.020652 DBG publisher.py:106 Gathering logs from all nodes
2019-03-03 13:18:41.222732 ERROR db_read.py:96 Node created
2019-03-03 13:18:41.424879 INFO db_write.py:48 Fanning out RPC
Traceback (most recent call last):
  File "./random_traceback.py", line 113, in get_random_error_string
  File "./random_traceback.py", line 92, in get_attributes
InvalidArgumentError: Provided too few arguments
2019-03-03 13:18:41.880056 ERROR fanout.py:190 Gathering node data
2019-03-03 13:18:41.930364 ERROR task_generator.py:98 Creating task
2019-03-03 13:18:42.031162 ERROR protobuf_parser.py:280 Combining logs from all nodes into single log file
2019-03-03 13:18:42.182724 ERROR audit_logger.py:157 Gathering logs from all nodes
2019-03-03 13:18:42.233305 ERROR wsgi_handler.py:269 Node destroyed
2019-03-03 13:18:42.636333 INFO scheduler.py:202 Node created
2019-03-03 13:18:43.140590 ERROR rpc_client.py:347 Creating task
2019-03-03 13:18:43.947105 ERROR audit_logger.py:35 Node destroyed
2019-03-03 13:18:44.350810 INFO fanout.py:178 Fanning out RPC
2019-03-03 13:18:44.754519 DBG ssh_tunnel.py:188 Gathering node data
Traceback (most recent call last):
  File "./random_traceback.py", line 103, in get_random_error_string
  File "./random_traceback.py", line 70, in extract_metadata
MissingAttributeError: Extra attribute needed
2019-03-03 13:18:45.258367 ERROR http_handler.py:122 Gathering node data
2019-03-03 13:18:45.813579 ERROR wsgi_handler.py:242 Node created
2019-03-03 13:18:45.964783 INFO fanout.py:121 Node created
2019-03-03 13:18:46.015185 INFO http_handler.py:363 Node created
2019-03-03 13:18:46.065609 INFO wsgi_handler.py:258 Node destroyed
2019-03-03 13:18:46.115996 ERROR publisher.py:228 Gathering logs from all nodes
2019-03-03 13:18:46.217069 DBG alert_manager.py:202 Creating task
2019-03-03 13:18:46.267516 INFO alert_manager.py:218 Combining logs from all nodes into single log file
Traceback (most recent call last):
  File "./random_traceback.py", line 108, in get_random_error_string
  File "./random_traceback.py", line 81, in return_output
BadRequestError: Request buffer too large
2019-03-03 13:18:46.772038 INFO rpc_client.py:344 Creating task
2019-03-03 13:18:46.822550 ERROR ssh_tunnel.py:125 Creating task
Traceback (most recent call last):
  File "./random_traceback.py", line 108, in get_random_error_string
  File "./random_traceback.py", line 75, in return_output
  File "./random_traceback.py", line 66, in extract_metadata
  File "./random_traceback.py", line 77, in return_output
  File "./random_traceback.py", line 53, in get_data
  File "./random_traceback.py", line 70, in extract_metadata
InvalidArgumentError: Provided too many arguments
2019-03-03 13:18:47.378730 DBG db_read.py:85 Fanning out RPC
2019-03-03 13:18:47.479641 INFO publisher.py:85 Gathering logs from all nodes
2019-03-03 13:18:47.581065 DBG http_handler.py:94 Node created
2019-03-03 13:18:47.782573 DBG wsgi_handler.py:18 Creating task
Traceback (most recent call last):
  File "./random_traceback.py", line 98, in get_random_error_string
  File "./random_traceback.py", line 59, in get_data
ConflictError: Conflicting data types
2019-03-03 13:18:49.397420 INFO ssh_tunnel.py:376 Creating task
2019-03-03 13:18:49.699051 DBG log_collector.py:284 Generated binary file
2019-03-03 13:18:49.950685 INFO alert_manager.py:326 Gathering node data
2019-03-03 13:18:50.505359 DBG scheduler.py:291 Node created
2019-03-03 13:18:51.211119 ERROR audit_logger.py:229 Generated binary file
2019-03-03 13:18:51.261450 INFO rpc_client.py:355 Generated binary file
2019-03-03 13:18:51.412779 ERROR alert_manager.py:211 Fanning out RPC
2019-03-03 13:18:52.418665 DBG rpc_client.py:331 Generated binary file
2019-03-03 13:18:52.671073 ERROR scheduler.py:390 Combining logs from all nodes into single log file
2019-03-03 13:18:52.872692 INFO http_handler.py:395 Node destroyed
2019-03-03 13:18:52.923185 INFO http_handler.py:300 Node destroyed
2019-03-03 13:18:53.579052 INFO log_collector.py:13 Node destroyed
2019-03-03 13:18:53.780471 ERROR scheduler.py:22 Gathering logs from all nodes
Traceback (most recent call last):
  File "./random_traceback.py", line 113, in get_random_error_string
  File "./random_traceback.py", line 92, in get_attributes
BadRequestError: Request buffer too small
2019-03-03 13:18:54.031915 ERROR gflags_handler.py:210 Fanning out RPC
2019-03-03 13:18:54.233557 DBG fanout.py:400 Generated binary file
2019-03-03 13:18:54.989096 DBG task_generator.py:380 Fanning out RPC
2019-03-03 13:18:55.341876 ERROR task_generator.py:56 Generated binary file
2019-03-03 13:18:55.443421 INFO log_collector.py:37 Gathering logs from all nodes
2019-03-03 13:18:55.848420 INFO gflags_handler.py:149 Combining logs from all nodes into single log file
2019-03-03 13:18:56.051080 ERROR log_collector.py:389 Node destroyed
2019-03-03 13:18:56.307067 ERROR alert_manager.py:364 Gathering node data
Traceback (most recent call last):
  File "./random_traceback.py", line 113, in get_random_error_string
  File "./random_traceback.py", line 92, in get_attributes
BasicAuthRequiredError: Invalid authentication
2019-03-03 13:18:57.072569 DBG task_generator.py:263 Gathering node data
2019-03-03 13:18:57.226561 ERROR rpc_client.py:69 Generated binary file
2019-03-03 13:18:57.481052 DBG scheduler.py:206 Node created
2019-03-03 13:18:57.786537 ERROR fanout.py:134 Gathering node data
2019-03-03 13:18:57.838208 INFO log_collector.py:73 Gathering node data
2019-03-03 13:18:58.348169 ERROR protobuf_parser.py:44 Node destroyed
2019-03-03 13:18:58.499521 DBG ssh_tunnel.py:344 Combining logs from all nodes into single log file
2019-03-03 13:18:58.752669 INFO alert_manager.py:227 Node destroyed
2019-03-03 13:18:59.663749 INFO http_handler.py:332 Node destroyed
2019-03-03 13:19:00.217393 INFO protobuf_parser.py:305 Gathering logs from all nodes
2019-03-03 13:19:00.318397 DBG ssh_tunnel.py:1 Combining logs from all nodes into single log file
2019-03-03 13:19:00.469761 DBG db_write.py:359 Node created
2019-03-03 13:19:00.620427 INFO publisher.py:390 Creating task
2019-03-03 13:19:01.177622 DBG log_collector.py:224 Fanning out RPC
2019-03-03 13:19:01.378607 ERROR publisher.py:341 Generated binary file
2019-03-03 13:19:02.087237 ERROR http_handler.py:134 Fanning out RPC
2019-03-03 13:19:02.340633 INFO publisher.py:289 Fanning out RPC
2019-03-03 13:19:02.391331 DBG http_handler.py:269 Generated binary file
Traceback (most recent call last):
  File "./random_traceback.py", line 108, in get_random_error_string
  File "./random_traceback.py", line 77, in return_output
  File "./random_traceback.py", line 53, in get_data
  File "./random_traceback.py", line 70, in extract_metadata
ConflictError: Conflicting data types
2019-03-03 13:19:02.644144 DBG http_handler.py:282 Node created
2019-03-03 13:19:03.149834 INFO protobuf_parser.py:309 Gathering logs from all nodes
